<?xml version="1.0" encoding="UTF-8"?>
<testsuite name="calculater_tests.CalculatorTest-20220415115609" tests="5" file="calculater_tests.py" time="0.068" timestamp="2022-04-15T11:56:11" failures="2" errors="1" skipped="0">
	<testcase classname="calculater_tests.CalculatorTest" name="test_add" time="0.005" timestamp="2022-04-15T11:56:11"/>
	<testcase classname="calculater_tests.CalculatorTest" name="test_substract_from_result" time="0.006" timestamp="2022-04-15T11:56:11"/>
	<testcase classname="calculater_tests.CalculatorTest" name="test_substract_by_result" time="0.017" timestamp="2022-04-15T11:56:11">
		<failure type="AssertionError" message="None != 3 : Should be 3"><![CDATA[Traceback (most recent call last):
  File "D:\Programs\Python\Python310\lib\unittest\case.py", line 59, in testPartExecutor
    yield
  File "D:\Programs\Python\Python310\lib\unittest\case.py", line 591, in run
    self._callTestMethod(testMethod)
  File "D:\Programs\Python\Python310\lib\unittest\case.py", line 549, in _callTestMethod
    method()
  File "d:\projects\dot503-basic-calculator\src\unittest\python\calculater_tests.py", line 21, in test_substract_by_result
    self.assertEqual(calculator.calculate(
  File "D:\Programs\Python\Python310\lib\unittest\case.py", line 845, in assertEqual
    assertion_func(first, second, msg=msg)
  File "D:\Programs\Python\Python310\lib\unittest\case.py", line 838, in _baseAssertEqual
    raise self.failureException(msg)
AssertionError: None != 3 : Should be 3
]]></failure>
	</testcase>
	<testcase classname="calculater_tests.CalculatorTest" name="test_zero_division" time="0.015" timestamp="2022-04-15T11:56:11">
		<failure type="AssertionError" message="Division by 0 not handled"><![CDATA[Traceback (most recent call last):
  File "D:\Programs\Python\Python310\lib\unittest\case.py", line 59, in testPartExecutor
    yield
  File "D:\Programs\Python\Python310\lib\unittest\case.py", line 591, in run
    self._callTestMethod(testMethod)
  File "D:\Programs\Python\Python310\lib\unittest\case.py", line 549, in _callTestMethod
    method()
  File "d:\projects\dot503-basic-calculator\src\unittest\python\calculater_tests.py", line 33, in test_zero_division
    self.fail("Division by 0 not handled")
  File "D:\Programs\Python\Python310\lib\unittest\case.py", line 675, in fail
    raise self.failureException(msg)
AssertionError: Division by 0 not handled
]]></failure>
	</testcase>
	<testcase classname="calculater_tests.CalculatorTest" name="test_string_inputs" time="0.025" timestamp="2022-04-15T11:56:11">
		<error type="TypeError" message="'NoneType' object is not callable"><![CDATA[Traceback (most recent call last):
  File "D:\Programs\Python\Python310\lib\unittest\case.py", line 59, in testPartExecutor
    yield
  File "D:\Programs\Python\Python310\lib\unittest\case.py", line 591, in run
    self._callTestMethod(testMethod)
  File "D:\Programs\Python\Python310\lib\unittest\case.py", line 549, in _callTestMethod
    method()
  File "d:\projects\dot503-basic-calculator\src\unittest\python\calculater_tests.py", line 26, in test_string_inputs
    self.assertRaises(ValueError, calculator.calculate(['x', '-', 'y']))
  File "D:\Programs\Python\Python310\lib\unittest\case.py", line 738, in assertRaises
    return context.handle('assertRaises', args, kwargs)
  File "D:\Programs\Python\Python310\lib\unittest\case.py", line 201, in handle
    callable_obj(*args, **kwargs)
TypeError: 'NoneType' object is not callable
]]></error>
	</testcase>
</testsuite>
