{
  "errors": [],
  "failures": [
    {
      "test": "calculater_tests.CalculatorTest.test_add",
      "traceback": "Traceback (most recent call last):\n  File \"D:\\Programs\\Python\\Python310\\lib\\unittest\\case.py\", line 59, in testPartExecutor\n    yield\n  File \"D:\\Programs\\Python\\Python310\\lib\\unittest\\case.py\", line 591, in run\n    self._callTestMethod(testMethod)\n  File \"D:\\Programs\\Python\\Python310\\lib\\unittest\\case.py\", line 549, in _callTestMethod\n    method()\n  File \"d:\\projects\\dot503a2_test\\src\\unittest\\python\\calculater_tests.py\", line 9, in test_add\n    self.assertEqual(calculator.calculate(\n  File \"D:\\Programs\\Python\\Python310\\lib\\unittest\\case.py\", line 845, in assertEqual\n    assertion_func(first, second, msg=msg)\n  File \"D:\\Programs\\Python\\Python310\\lib\\unittest\\case.py\", line 838, in _baseAssertEqual\n    raise self.failureException(msg)\nAssertionError: None != 3 : Should be 3\n"
    },
    {
      "test": "calculater_tests.CalculatorTest.test_float_inputs",
      "traceback": "Traceback (most recent call last):\n  File \"D:\\Programs\\Python\\Python310\\lib\\unittest\\case.py\", line 59, in testPartExecutor\n    yield\n  File \"D:\\Programs\\Python\\Python310\\lib\\unittest\\case.py\", line 591, in run\n    self._callTestMethod(testMethod)\n  File \"D:\\Programs\\Python\\Python310\\lib\\unittest\\case.py\", line 549, in _callTestMethod\n    method()\n  File \"d:\\projects\\dot503a2_test\\src\\unittest\\python\\calculater_tests.py\", line 14, in test_float_inputs\n    self.assertEqual(calculator.calculate(\n  File \"D:\\Programs\\Python\\Python310\\lib\\unittest\\case.py\", line 845, in assertEqual\n    assertion_func(first, second, msg=msg)\n  File \"D:\\Programs\\Python\\Python310\\lib\\unittest\\case.py\", line 838, in _baseAssertEqual\n    raise self.failureException(msg)\nAssertionError: None != 1 : Should be 1\n"
    },
    {
      "test": "calculater_tests.CalculatorTest.test_substract_by_result",
      "traceback": "Traceback (most recent call last):\n  File \"D:\\Programs\\Python\\Python310\\lib\\unittest\\case.py\", line 59, in testPartExecutor\n    yield\n  File \"D:\\Programs\\Python\\Python310\\lib\\unittest\\case.py\", line 591, in run\n    self._callTestMethod(testMethod)\n  File \"D:\\Programs\\Python\\Python310\\lib\\unittest\\case.py\", line 549, in _callTestMethod\n    method()\n  File \"d:\\projects\\dot503a2_test\\src\\unittest\\python\\calculater_tests.py\", line 26, in test_substract_by_result\n    self.assertEqual(calculator.calculate(\n  File \"D:\\Programs\\Python\\Python310\\lib\\unittest\\case.py\", line 845, in assertEqual\n    assertion_func(first, second, msg=msg)\n  File \"D:\\Programs\\Python\\Python310\\lib\\unittest\\case.py\", line 838, in _baseAssertEqual\n    raise self.failureException(msg)\nAssertionError: 6.0 != 3 : Should be 3\n"
    },
    {
      "test": "calculater_tests.CalculatorTest.test_substract_from_result",
      "traceback": "Traceback (most recent call last):\n  File \"D:\\Programs\\Python\\Python310\\lib\\unittest\\case.py\", line 59, in testPartExecutor\n    yield\n  File \"D:\\Programs\\Python\\Python310\\lib\\unittest\\case.py\", line 591, in run\n    self._callTestMethod(testMethod)\n  File \"D:\\Programs\\Python\\Python310\\lib\\unittest\\case.py\", line 549, in _callTestMethod\n    method()\n  File \"d:\\projects\\dot503a2_test\\src\\unittest\\python\\calculater_tests.py\", line 20, in test_substract_from_result\n    self.assertEqual(calculator.calculate(\n  File \"D:\\Programs\\Python\\Python310\\lib\\unittest\\case.py\", line 845, in assertEqual\n    assertion_func(first, second, msg=msg)\n  File \"D:\\Programs\\Python\\Python310\\lib\\unittest\\case.py\", line 838, in _baseAssertEqual\n    raise self.failureException(msg)\nAssertionError: None != 3 : Should be 3\n"
    }
  ],
  "tests-run": 5
}