
Running tests...
----------------------------------------------------------------------
FFFF.
======================================================================
FAIL [0.026s]: test_add (calculater_tests.CalculatorTest)
----------------------------------------------------------------------
Traceback (most recent call last):
  File "D:\Programs\Python\Python310\lib\unittest\case.py", line 59, in testPartExecutor
    yield
  File "D:\Programs\Python\Python310\lib\unittest\case.py", line 591, in run
    self._callTestMethod(testMethod)
  File "D:\Programs\Python\Python310\lib\unittest\case.py", line 549, in _callTestMethod
    method()
  File "d:\projects\dot503a2_test\src\unittest\python\calculater_tests.py", line 9, in test_add
    self.assertEqual(calculator.calculate(
  File "D:\Programs\Python\Python310\lib\unittest\case.py", line 845, in assertEqual
    assertion_func(first, second, msg=msg)
  File "D:\Programs\Python\Python310\lib\unittest\case.py", line 838, in _baseAssertEqual
    raise self.failureException(msg)
AssertionError: None != 3 : Should be 3

======================================================================
FAIL [0.017s]: test_float_inputs (calculater_tests.CalculatorTest)
----------------------------------------------------------------------
Traceback (most recent call last):
  File "D:\Programs\Python\Python310\lib\unittest\case.py", line 59, in testPartExecutor
    yield
  File "D:\Programs\Python\Python310\lib\unittest\case.py", line 591, in run
    self._callTestMethod(testMethod)
  File "D:\Programs\Python\Python310\lib\unittest\case.py", line 549, in _callTestMethod
    method()
  File "d:\projects\dot503a2_test\src\unittest\python\calculater_tests.py", line 14, in test_float_inputs
    self.assertEqual(calculator.calculate(
  File "D:\Programs\Python\Python310\lib\unittest\case.py", line 845, in assertEqual
    assertion_func(first, second, msg=msg)
  File "D:\Programs\Python\Python310\lib\unittest\case.py", line 838, in _baseAssertEqual
    raise self.failureException(msg)
AssertionError: None != 1 : Should be 1

======================================================================
FAIL [0.018s]: test_substract_by_result (calculater_tests.CalculatorTest)
----------------------------------------------------------------------
Traceback (most recent call last):
  File "D:\Programs\Python\Python310\lib\unittest\case.py", line 59, in testPartExecutor
    yield
  File "D:\Programs\Python\Python310\lib\unittest\case.py", line 591, in run
    self._callTestMethod(testMethod)
  File "D:\Programs\Python\Python310\lib\unittest\case.py", line 549, in _callTestMethod
    method()
  File "d:\projects\dot503a2_test\src\unittest\python\calculater_tests.py", line 26, in test_substract_by_result
    self.assertEqual(calculator.calculate(
  File "D:\Programs\Python\Python310\lib\unittest\case.py", line 845, in assertEqual
    assertion_func(first, second, msg=msg)
  File "D:\Programs\Python\Python310\lib\unittest\case.py", line 838, in _baseAssertEqual
    raise self.failureException(msg)
AssertionError: 6.0 != 3 : Should be 3

======================================================================
FAIL [0.024s]: test_substract_from_result (calculater_tests.CalculatorTest)
----------------------------------------------------------------------
Traceback (most recent call last):
  File "D:\Programs\Python\Python310\lib\unittest\case.py", line 59, in testPartExecutor
    yield
  File "D:\Programs\Python\Python310\lib\unittest\case.py", line 591, in run
    self._callTestMethod(testMethod)
  File "D:\Programs\Python\Python310\lib\unittest\case.py", line 549, in _callTestMethod
    method()
  File "d:\projects\dot503a2_test\src\unittest\python\calculater_tests.py", line 20, in test_substract_from_result
    self.assertEqual(calculator.calculate(
  File "D:\Programs\Python\Python310\lib\unittest\case.py", line 845, in assertEqual
    assertion_func(first, second, msg=msg)
  File "D:\Programs\Python\Python310\lib\unittest\case.py", line 838, in _baseAssertEqual
    raise self.failureException(msg)
AssertionError: None != 3 : Should be 3

----------------------------------------------------------------------
Ran 5 tests in 0.247s

FAILED (failures=4)

Generating XML reports...
